inst/extdata/tradersample.txt
type,time,id,price,size,type,status
A,30770152,1165596,25.88,350,BID,FALSE
A,29846657,786221,25.86,310,BID,FALSE
A,30404845,1029272,25.86,50,BID,FALSE
A,30768287,1201887,25.85,700,BID,FALSE
A,30795459,1221749,25.84,800,BID,FALSE
A,30690039,1170953,25.79,1000,BID,FALSE
A,28139634,401355,25.78,100,BID,FALSE
A,29951333,812647,25.76,100,BID,FALSE
A,25202631,527,25.7,1830,BID,FALSE
A,30707659,1176366,25.7,500,BID,FALSE
A,30501324,1078810,25.21,1400,BID,FALSE
A,30117845,887647,25.11,25,BID,FALSE
A,28905126,546224,22.05,50,BID,FALSE
A,29029394,582496,22.0,200,BID,FALSE
A,27000480,221374,0.01,100,BID,FALSE
A,27617483,326224,0.01,100,BID,FALSE
A,30691134,1171344,25.9,500,ASK,FALSE
A,29572003,726303,25.92,500,ASK,FALSE
A,29058617,589422,26.05,500,ASK,FALSE
A,30501330,1078812,26.11,1400,ASK,FALSE
A,29974242,817159,26.5,5000,ASK,FALSE
A,29976511,817472,26.5,5000,ASK,FALSE
A,29980601,818526,26.5,5000,ASK,FALSE
A,30001552,826011,26.5,1250,ASK,FALSE
A,28852685,534384,26.98,50,ASK,FALSE
A,28867982,537195,27.5,25,ASK,FALSE
A,28926351,551940,31.86,500,ASK,FALSE
A,28931843,552878,32.83,500,ASK,FALSE
A,28800593,515786,34.0,17500,ASK,FALSE
A,28937702,554014,34.01,40,ASK,FALSE
A,28500436,458216,100.84,100,ASK,FALSE
A,27617483,326225,2000.0,100,ASK,FALSE
T,30770152,3250,25.88,100,FALSE
A,30814563,1229864,25.3,147,BID,FALSE
C,30814563,1229864
C,30814983,1221749
C,30815171,1201887
A,30815171,1230507,25.83,900,BID,FALSE
A,30815248,1230676,25.84,700,BID,FALSE
C,30815506,1230676
C,30815506,1230507
A,30815583,1231230,25.83,800,BID,FALSE
A,30815583,1231232,25.84,700,BID,FALSE
C,30828481,1231232
C,30828481,1231230
A,30828558,1241242,25.83,1000,BID,FALSE
A,30839564,1247118,25.3,172,BID,FALSE
C,30839564,1247118
R,30840936,1241242,800
A,30840936,1247611,25.84,900,BID,FALSE
A,30864564,1261009,25.3,197,BID,FALSE
C,30864565,1261009
A,30889565,1270833,25.3,122,BID,FALSE
C,30889566,1270833
R,30891133,1165596,50
T,30891133,3550,25.88,300,FALSE
R,30891715,1247611,700
A,30900117,1274736,1.0,1,BID,FALSE
C,30900126,1274736
A,30914566,1282587,25.3,147,BID,FALSE
C,30914567,1282587
A,30939566,1295133,25.3,172,BID,FALSE
C,30939567,1295133
A,30943520,1298939,25.99,300,ASK,FALSE
A,30964567,1314031,25.3,197,BID,FALSE
C,30964568,1314031
A,30989568,1323229,25.3,122,BID,FALSE
C,30989569,1323229
R,30996335,1241242,700
C,30996335,1247611
A,31014568,1333297,25.3,147,BID,FALSE
C,31014569,1333297
A,31018582,1334755,25.83,300,BID,FALSE
C,31018591,1334755
A,31027882,1342158,25.83,300,BID,FALSE
C,31027883,1342158
A,31027960,1342238,25.83,300,BID,FALSE
C,31028020,1342238
A,31033219,1343919,25.83,300,BID,FALSE
C,31034539,1343919
A,31039570,1348868,25.3,172,BID,FALSE
C,31039570,1348868
A,31049976,1353408,25.87,100,BID,FALSE
A,31050028,1353426,25.86,100,BID,FALSE
A,31050122,1353590,25.85,100,BID,FALSE
A,31050176,1353636,25.84,100,BID,FALSE
A,31050420,1353742,25.83,100,BID,FALSE
A,31050535,1353884,25.82,100,BID,FALSE
A,31050655,1354035,25.81,100,BID,FALSE
A,31050836,1354175,25.8,100,BID,FALSE
A,31050976,1354283,25.79,100,BID,FALSE
A,31051027,1354327,25.78,100,BID,FALSE
A,31051088,1354406,25.77,100,BID,FALSE
A,31051323,1354518,25.76,100,BID,FALSE
A,31051373,1354559,25.75,100,BID,FALSE
A,31051678,1354685,25.74,100,BID,FALSE
A,31051801,1354765,25.73,100,BID,FALSE
A,31051851,1354863,25.72,100,BID,FALSE
A,31051976,1354979,25.71,100,BID,FALSE
A,31052067,1355064,25.7,100,BID,FALSE
A,31052122,1355141,25.88,100,BID,FALSE
A,31052679,1355436,25.69,100,BID,FALSE
A,31052825,1355490,25.89,100,ASK,FALSE
A,31052976,1355583,25.9,100,ASK,FALSE
A,31052977,1355584,26.06,100,ASK,FALSE
A,31052977,1355586,26.07,100,ASK,FALSE
A,31052977,1355588,26.05,100,ASK,FALSE
A,31052977,1355589,26.03,100,ASK,FALSE
A,31052977,1355591,26.04,100,ASK,FALSE
A,31052977,1355593,26.0,100,ASK,FALSE
A,31052977,1355595,26.02,100,ASK,FALSE
A,31052977,1355597,26.08,100,ASK,FALSE
A,31052977,1355599,26.01,100,ASK,FALSE
A,31052977,1355601,25.98,100,ASK,FALSE
A,31052977,1355603,25.94,100,ASK,FALSE
A,31052977,1355605,25.99,100,ASK,FALSE
A,31052977,1355606,25.93,100,ASK,FALSE
A,31052977,1355608,25.97,100,ASK,FALSE
A,31052977,1355610,25.91,100,ASK,FALSE
A,31052977,1355612,25.96,100,ASK,FALSE
A,31052977,1355614,25.92,100,ASK,FALSE
A,31052977,1355618,25.95,100,ASK,FALSE
A,31058244,1358342,25.83,300,BID,FALSE
C,31060644,1358342
A,31060721,1360024,25.83,300,BID,FALSE
C,31060786,1360024
A,31064571,1361890,25.3,197,BID,FALSE
C,31064571,1361890
A,31071556,1365606,25.83,300,BID,FALSE
C,31081339,1365606
A,31081486,1369845,25.83,300,BID,FALSE
C,31081508,1369845
A,31083762,1370703,25.83,300,BID,FALSE
C,31083765,1370703
A,31083843,1370757,25.83,300,BID,FALSE
C,31087510,1370757
A,31087587,1372202,25.83,300,BID,FALSE
A,31089557,1373069,25.3,122,BID,FALSE
C,31089558,1373069
C,31090123,1372202
A,31091187,1373733,25.83,300,BID,FALSE
C,31091768,1373733
A,31094816,1375616,25.83,300,BID,FALSE
A,31114555,1382136,25.3,147,BID,FALSE
C,31114556,1382136
A,31133396,1388890,40.0,1,ASK,FALSE
C,31138256,1388890
A,31139556,1395253,25.3,172,BID,FALSE
C,31139557,1395253
C,31144778,1375616
A,31144987,1398029,25.83,300,BID,FALSE
C,31145010,1398029
A,31164557,1411345,25.3,197,BID,FALSE
C,31164558,1411345
A,31166676,1411938,14.01,100,BID,FALSE
A,31168100,1412437,25.83,300,BID,FALSE
C,31168139,1412437
A,31168314,1412518,25.83,300,BID,FALSE
C,31168345,1412518
A,31172124,1413775,25.83,300,BID,FALSE
C,31172291,1413775
C,31172990,1165596
T,31172990,3600,25.88,50,FALSE
R,31172990,1355141,50
T,31172990,3650,25.88,50,FALSE
C,31172990,1355141
A,31173067,1414405,25.82,900,BID,FALSE
R,31181821,1414405,600
A,31181821,1416829,25.83,300,BID,FALSE
C,31182468,1416829
A,31182545,1417028,25.83,300,BID,FALSE
A,31184620,1420003,24.6,1000,BID,FALSE
A,31189275,1424688,25.88,170,BID,FALSE
A,31189275,1424690,25.88,100,BID,FALSE
A,31189557,1424830,25.3,122,BID,FALSE
C,31189558,1424830
A,31200794,1429208,1.0,1,BID,FALSE
C,31200800,1429208
A,31200815,1429216,1.0,1,BID,FALSE
C,31200817,1429216
A,31214558,1434368,25.3,147,BID,FALSE
C,31214559,1434368
A,31239559,1442520,25.3,172,BID,FALSE
C,31239560,1442520
C,31241575,1417028
C,31241575,1414405
A,31241575,1443152,25.84,900,BID,FALSE
R,31252402,1443152,700
R,31253846,1424688,160
T,31253846,3660,25.88,10,FALSE
R,31257006,1443152,500
A,31257083,1448710,25.83,300,BID,FALSE
A,31264560,1451651,25.3,197,BID,FALSE
C,31264561,1451651
C,31289425,1448710
R,31289425,1241242,500
A,31289561,1458813,25.3,122,BID,FALSE
C,31289562,1458813
A,31314562,1470763,25.3,147,BID,FALSE
C,31314563,1470763
A,31320924,1475394,25.83,500,BID,FALSE
C,31329521,1443152
R,31329521,1475394,400
C,31339017,1424688
T,31339017,3820,25.88,160,FALSE
C,31339017,1424690
T,31339017,3920,25.88,100,FALSE
A,31339017,1489910,25.88,40,ASK,FALSE
A,31339018,1489912,25.88,100,ASK,FALSE
A,31339094,1489985,25.82,700,BID,FALSE
A,31339562,1490382,25.3,172,BID,FALSE
C,31339563,1490382
R,31343770,1475394,300
C,31343770,1489985
A,31343770,1494685,25.84,700,BID,FALSE
C,31361148,1029272
C,31361148,1489910
T,31361148,3960,25.88,40,FALSE
R,31361148,1489912,90
T,31361148,3970,25.88,10,FALSE
C,31361148,1489912
A,31361148,1511832,26.09,100,ASK,FALSE
A,31364563,1513734,25.3,197,BID,FALSE
C,31364564,1513734
R,31367694,1475394,100
A,31367694,1515110,25.84,300,BID,FALSE
C,31370485,1515110
A,31370562,1517321,25.83,300,BID,FALSE
R,31373770,1517321,200
A,31389564,1531751,25.3,122,BID,FALSE
C,31389565,1531751
A,31398932,1537239,26.05,1000,ASK,FALSE
C,31398988,1517321
A,31398988,1537264,25.84,300,BID,FALSE
C,31408283,1537264
A,31408360,1542328,25.83,300,BID,FALSE
A,31408422,1542401,25.84,300,BID,FALSE
C,31408422,1542328
C,31409008,1542401
A,31409085,1542762,25.83,300,BID,FALSE
C,31411885,1542762
A,31411885,1546265,25.84,300,BID,FALSE
C,31412111,1546265
A,31412188,1546578,25.83,300,BID,FALSE
A,31414565,1547839,25.3,147,BID,FALSE
C,31414566,1547839
R,31424911,1546578,200
A,31439565,1563694,25.3,172,BID,FALSE
C,31439566,1563694
C,31462869,1546578
A,31462869,1575140,25.84,300,BID,FALSE
C,31462874,1475394
C,31463075,1241242
R,31463075,1575140,100
A,31463075,1575634,25.85,700,BID,FALSE
